<?xml version="1.0"?>
<robot xmlns:xacro="http://www.ros.org/wiki/xacro"  name="robot">

    <!-- This is an example of a URDF. -->
    <!-- As we move through the file, new things to note will be pointed out. -->
    <!-- It's not meant an example of GOOD design, but an example of some of the various features of URDF/xacro. -->



    <!-- This will include all the contents of example_include.xacro first. Go check it out! -->
    <xacro:include filename="example_include.xacro" />



    <!-- This first link called "world" is empty -->
    <link name="world"></link>


    <!-- A simple fixed joint from our empty world link, to our base. -->
    <!-- The base origin is offset from the world origin. -->
    <joint name="base_joint" type="fixed">
        <origin xyz="0 0 0" rpy="1.57 0 0"/>
        <parent link="world"/>
        <child link="link_0"/>        
    </joint>


    <!-- base_link is a large rectangular plate. Some things to note: -->
    <!-- - We set the visual origin Z to half the box height, so that the link origin sits at the bottom of the box -->
    <!-- - We set the collision to be identical to the visual -->
    <!-- - We specified the colour manually (but still need to enter a name) -->
    <!-- - We specified all the inertial parameters manually -->
    <link name="link_0">
        <visual>
            <origin xyz="0 0 0.0" rpy="0 0 0"/>
            <geometry>
                <!-- <box size="2.5 1.5 0.1" /> -->
                <mesh filename="file:///$(find advance_control)/meshes/link_0_new.stl"/>
            </geometry>
            <material name="green">
                <color rgba="0.2 1 0.2 1"/>
            </material>
        </visual>
        <collision>
            <origin xyz="0 0 0.0" rpy="0 0 0"/>
            <contact_coefficients mu="0" kp="1000.0" kd="1.0"/>
            <geometry>
                <mesh filename="file:///$(find advance_control)/meshes/link_0_new.stl"/>
                <!-- <box size="2.5 1.5 0.1" /> -->
            </geometry>
        </collision>
        <inertial>
            <origin xyz="0 0 0.05" rpy="0 0 0"/>
            <mass value="120" />
            <inertia ixx="46587.58" ixy="0.0" ixz="0.0" iyy="115624.43" iyz="0.0" izz="108480.07" />
        </inertial>
    </link>

    <joint name="joint_0" type="fixed">
        <parent link="link_0"/>
        <child link="link_1"/>
        <origin rpy="0 0 0" xyz="0 0 0"/>
        <axis xyz="0 0 1"/>
        <limit lower="-3.14" upper="3.14" effort="1000" velocity="0.5"/>
    </joint>


    <link name="link_1">
        <visual>
            <origin xyz="0 0 0.0" rpy="0 0 0"/>
            <geometry>
                <!-- <box size="2.5 1.5 0.1" /> -->
                <mesh filename="file:///$(find advance_control)/meshes/link_1_new.stl"/>
            </geometry>
            <material name="green">
                <color rgba="0.2 1 0.2 1"/>
            </material>
        </visual>
        <collision>
            <origin xyz="0 0 0.0" rpy="0 0 0"/>
            <contact_coefficients mu="0" kp="1000.0" kd="1.0"/>
            <geometry>
                <mesh filename="file:///$(find advance_control)/meshes/link_1_new.stl"/>
                <!-- <box size="0.01 0.01 0.01" /> -->
            </geometry>
        </collision>
        <inertial>
            <origin xyz="0 0 0.0" rpy="0 0 0"/>
            <mass value="25" />
            <inertia ixx="251208.61" ixy="0.0" ixz="0.0" iyy="63579.55" iyz="0.0" izz="288777.52" />
        </inertial>
    </link>

    <joint name="joint_1" type="revolute">
        <parent link="link_0"/>
        <child link="link_1"/>
        <origin rpy="0 0 1.57" xyz="0 0.035 0"/>
        <axis xyz="0 0 1"/>
        <limit lower="-1.57" upper="1.57" effort="1000" velocity="0.5"/>
        <dynamics damping="0" friction="0"/>
    </joint>


    <link name="link_2">
        <visual>
            <origin xyz="0 0 0.0" rpy="0 0 -1.57"/>
            <geometry>
                <!-- <box size="2.5 1.5 0.1" /> -->
                <mesh filename="file:///$(find advance_control)/meshes/link_2_new.stl"/>
            </geometry>
            <material name="green">
                <color rgba="0.2 1 0.2 1"/>
            </material>
        </visual>
        <collision>
            <contact_coefficients mu="0" kp="1000.0" kd="1.0"/>
            <origin xyz="0 0 0.0" rpy="0 0 0"/>
            <geometry>
                <!-- <box size="0.01 0.01 0.01" /> -->
                <mesh filename="file:///$(find advance_control)/meshes/link_2_new.stl"/>
                <!-- <box size="2.5 1.5 0.1" /> -->
            </geometry>
        </collision>
        <inertial>
            <origin xyz="0 0 0.0" rpy="0 0 0"/>
            <mass value="15" />
            <inertia ixx="354300.22" ixy="0.0" ixz="0.0" iyy="91162.49" iyz="0.0" izz="411236.61" />
        </inertial>
    </link>

    <joint name="joint_2" type="revolute">
        <parent link="link_1"/>
        <child link="link_2"/>
        <origin rpy="0 0 0" xyz="0.12 0 0"/>
        <axis xyz="0 0 1"/>
        <limit lower="-3.14" upper="3.14" effort="0.5" velocity="0.5"/>
        <dynamics damping="10" friction="10"/>
    </joint>



    <link name="link_3">
        <visual>
            <origin xyz="0 0 0.0" rpy="0 0 0"/>
            <geometry>
                <mesh filename="file:///$(find advance_control)/meshes/link_3_new.stl"/>
            </geometry>
            <material name="green">
                <color rgba="0.2 1 0.2 1"/>
            </material>
        </visual>
        <collision>
            <contact_coefficients mu="0" kp="1000.0" kd="1.0"/>
            <origin xyz="0 0 0.0" rpy="0 0 0"/>
            <geometry>
                <mesh filename="file:///$(find advance_control)/meshes/link_3_new.stl"/>
            </geometry>
        </collision>
        <inertial>
            <origin xyz="0 0 0.0" rpy="0 0 0"/>
            <mass value="5" />
            <inertia ixx="6170.76" ixy="0.0" ixz="0.0" iyy="4149.40" iyz="0.0" izz="6170.76" />
        </inertial>
    </link>

    <joint name="joint_3" type="revolute">
        <parent link="link_2"/>
        <child link="link_3"/>
        <origin rpy="1.57 0 0" xyz="0 -0.175 0"/>
        <axis xyz="0 0 1"/>
        <limit lower="-3.14" upper="3.14" effort="1000" velocity="0.5"/>
        <dynamics damping="10" friction="10"/>
    </joint>



    <joint name="joint_eff" type="fixed">
        <parent link="link_3"/>
        <child link="end_effector"/>
        <origin rpy="0 -1.57 3.14" xyz="0 0 0.05"/>
        <axis xyz="0 0 1"/>
    </joint>
    
    <link name="end_effector">
    </link>


    <xacro:include filename="example_gazebo_velocity.xacro" />


</robot>